<?xml version="1.0" ?>
<robot xmlns:xacro="http://www.ros.org/wiki/xacro">

    <!-- All meshes are scaled by 0.001 in all dimensions because I exported in mm, ROS uses m-->

    <xacro:macro name="hexapod_base" params="parent">

        <joint name="base_attachment" type="fixed">
            <parent link="${parent}"/>
            <child link="body_link"/>
        </joint>

        <link name="body_link">
            <inertial>
                <origin xyz="0.0 0.0 0.0" rpy="0.0 0.0 0.0"/>
                <mass value="1"/>
                <inertia ixx="0.001" ixy="0.0" ixz="0.0" iyy="0.001" iyz="0.0" izz="0.001"/>
            </inertial>

            <visual>
                <origin xyz="0 0 0.0" rpy="0.0 0.0 0.0"/>
                <geometry>
                    <mesh filename="package://hexapod_description/meshes/visual/body.stl" scale="0.001 0.001 0.001"/>
                </geometry>
                <material name="Grey">
                    <color rgba="0.2 0.2 0.2 1"/>
                </material>
            </visual>

            <collision>
                <origin xyz="0.0 0.0 0.0" rpy="0.0 0.0 0.0"/>
                <geometry>
                    <mesh filename="package://hexapod_description/meshes/collision/body.stl" scale="0.001 0.001 0.001"/>
                </geometry>
            </collision>
        </link>
        
        
        <xacro:hexapod_leg xyz="0.1497 0.0797 0.0" rpy="0.0 0.0 0.738" suffix="lf"/>
        
        <xacro:hexapod_leg xyz="0.0 0.0795 0.0" rpy="0.0 0.0 ${pi/2.0}" suffix="lm"/>
        
        <xacro:hexapod_leg xyz="-0.1497 0.0797 0.0" rpy="0.0 0.0 2.404" suffix="lr"/>
        
        <xacro:hexapod_leg xyz="0.1497 -0.0797 0.0" rpy="0.0 0.0 -0.738" suffix="rf"/>
        
        <xacro:hexapod_leg xyz="0.0 -0.0795 0.0" rpy="0.0 0.0 -${pi/2.0}" suffix="rm"/>
        
        <xacro:hexapod_leg xyz="-0.1497 -0.0797 0.0" rpy="0.0 0.0 -2.404" suffix="rr"/>


        <joint name="camera_attachment" type="fixed">
            <parent link="body_link"/>
            <child link="front_camera_link"/>
            <origin xyz="0.33 0.0 0.04" rpy="0.0 0.0 0.0"/>
        </joint>

        <link name="front_camera_link">
            <inertial>
                <origin xyz="0.0 0.0 0.0" rpy="0.0 0.0 0.0"/>
                <mass value="1"/>
                <inertia ixx="0.001" ixy="0.0" ixz="0.0" iyy="0.001" iyz="0.0" izz="0.001"/>
            </inertial>

            <visual>
                <origin xyz="0 0 0.0" rpy="0.0 0.0 0.0"/>
                <geometry>
                    <mesh filename="package://hexapod_description/meshes/visual/camera.stl" scale="0.001 0.001 0.001"/>
                </geometry>
                <material name="Grey">
                    <color rgba="0.2 0.2 0.2 1"/>
                </material>
            </visual>

            <collision>
                <origin xyz="0.0 0.0 0.0" rpy="0.0 0.0 0.0"/>
                <geometry>
                    <mesh filename="package://hexapod_description/meshes/collision/camera.stl" scale="0.001 0.001 0.001"/>
                </geometry>
            </collision>
        </link>

        <joint name="lidar_attachment" type="fixed">
            <parent link="body_link"/>
            <child link="lidar_link"/>
            <origin xyz="0.275 0.0 0.079" rpy="0.0 0.0 0.0"/>
        </joint>

        <link name="lidar_link">
            <inertial>
                <origin xyz="0.0 0.0 0.0" rpy="0.0 0.0 0.0"/>
                <mass value="1"/>
                <inertia ixx="0.001" ixy="0.0" ixz="0.0" iyy="0.001" iyz="0.0" izz="0.001"/>
            </inertial>

            <visual>
                <origin xyz="0.0 0.0 0.0" rpy="0.0 0.0 0.0"/>
                <geometry>
                    <mesh filename="package://hexapod_description/meshes/visual/lidar.stl" scale="0.001 0.001 0.001"/>
                </geometry>
                <material name="Grey">
                    <color rgba="0.2 0.2 0.2 1"/>
                </material>
            </visual>

            <collision>
                <origin xyz="0.0 0.0 0.0" rpy="0.0 0.0 0.0"/>
                <geometry>
                    <mesh filename="package://hexapod_description/meshes/collision/lidar.stl" scale="0.001 0.001 0.001"/>
                </geometry>
            </collision>
        </link>
        

    </xacro:macro>




    <xacro:macro name="hexapod_leg" params="xyz rpy suffix">

        <joint name="coxa_joint_${suffix}" type="revolute">
            <parent link="body_link"/>
            <child link="coxa_link_${suffix}"/>
            <origin xyz="${xyz}" rpy="${rpy}"/>
            <axis xyz="0 0 1"/>
            <limit effort="87" velocity="5.6548668" lower="-2.6179939" upper="2.6179939" />
            <dynamics damping="1.0"/>
        </joint>

        <link name="coxa_link_${suffix}">
            <inertial>
                <origin xyz="0.0 0.0 0.0" rpy="0.0 0.0 0.0"/>
                <mass value="1"/>
                <inertia ixx="0.001" ixy="0.0" ixz="0.0" iyy="0.001" iyz="0.0" izz="0.001"/>
            </inertial>

            <visual>
                <origin xyz="0 0 0.0" rpy="0.0 0.0 0.0"/>
                <geometry>
                    <mesh filename="package://hexapod_description/meshes/visual/leg_link_1.stl" scale="0.001 0.001 0.001"/>
                </geometry>
                <material name="Grey">
                    <color rgba="0.2 0.2 0.2 1"/>
                </material>
            </visual>

            <collision>
                <origin xyz="0.0 0.0 0.0" rpy="0.0 0.0 0.0"/>
                <geometry>
                    <mesh filename="package://hexapod_description/meshes/collision/leg_link_1.stl" scale="0.001 0.001 0.001"/>
                </geometry>
            </collision>
        </link>

        <joint name="thigh_joint_${suffix}" type="revolute">
            <parent link="coxa_link_${suffix}"/>
            <child link="thigh_link_${suffix}"/>
            <origin xyz="0.1 0.0 0.0" rpy="0.0 0.0 0.0"/>
            <axis xyz="0 1 0"/>
            <limit effort="87" velocity="5.6548668" lower="-2.6179939" upper="2.6179939" />
            <dynamics damping="1.0"/>
        </joint>

        <link name="thigh_link_${suffix}">
            <inertial>
                <origin xyz="0.0 0.0 0.0" rpy="0.0 0.0 0.0"/>
                <mass value="1"/>
                <inertia ixx="0.001" ixy="0.0" ixz="0.0" iyy="0.001" iyz="0.0" izz="0.001"/>
            </inertial>

            <visual>
                <origin xyz="0 0 0.0" rpy="0.0 0.0 0.0"/>
                <geometry>
                    <mesh filename="package://hexapod_description/meshes/visual/leg_link_2.stl" scale="0.001 0.001 0.001"/>
                </geometry>
                <material name="Grey">
                    <color rgba="0.2 0.2 0.2 1"/>
                </material>
            </visual>

            <collision>
                <origin xyz="0.0 0.0 0.0" rpy="0.0 0.0 0.0"/>
                <geometry>
                    <mesh filename="package://hexapod_description/meshes/collision/leg_link_2.stl" scale="0.001 0.001 0.001"/>
                </geometry>
            </collision>
        </link>

        <joint name="tibia_joint_${suffix}" type="revolute">
            <parent link="thigh_link_${suffix}"/>
            <child link="tibia_link_${suffix}"/>
            <origin xyz="0.1199 0.0 0.07597" rpy="0.0 0.0 0.0"/>
            <axis xyz="0 1 0"/>
            <limit effort="87" velocity="5.6548668" lower="-2.6179939" upper="2.6179939" />
            <dynamics damping="1.0"/>
        </joint>

        <link name="tibia_link_${suffix}">
            <inertial>
                <origin xyz="0.0 0.0 0.0" rpy="0.0 0.0 0.0"/>
                <mass value="1"/>
                <inertia ixx="0.001" ixy="0.0" ixz="0.0" iyy="0.001" iyz="0.0" izz="0.001"/>
            </inertial>

            <visual>
                <origin xyz="0 0 0.0" rpy="0.0 0.0 0.0"/>
                <geometry>
                    <mesh filename="package://hexapod_description/meshes/visual/leg_link_3.stl" scale="0.001 0.001 0.001"/>
                </geometry>
                <material name="Grey">
                    <color rgba="0.2 0.2 0.2 1"/>
                </material>
            </visual>

            <collision>
                <origin xyz="0.0 0.0 0.0" rpy="0.0 0.0 0.0"/>
                <geometry>
                    <mesh filename="package://hexapod_description/meshes/collision/leg_link_3.stl" scale="0.001 0.001 0.001"/>
                </geometry>
            </collision>
        </link>

        <xacro:include filename="$(find hexapod_description)/urdf/hexapod.transmission.xacro"/>
        <xacro:leg_joint_transmission suffix="${suffix}"/>

    </xacro:macro>

</robot>